<?xml version="1.0"?>
<robot xmlns:xacro="https://www.ros.org/wiki/xacro">

    <xacro:include filename='inertial_macros.xacro'/>

    <!--SETTING UP MATERIAL AND COLORS-->
    <material name='white'>
        <color rgba='1 1 1 1' />
    </material>

    <material name='black'>
        <color rgba='0 0 0 1' />
    </material>

    <material name='blue'>
        <color rgba='0 0 1 1' />
    </material>

    <material name='red'>
        <color rgba='1 0 0 1' />
    </material>


    <!--CREAATING BASE LINK-->

    <link name='base_link'>

    </link>

    <!--BODY LINK-->

    <joint name='body_joint' type='fixed'>
        <parent link='base_link'/>
        <child link ='body'/>
        <origin xyz='-0.1 0 0'/>
    </joint>

    <link name='body'>
        <visual>
            <origin xyz='0.1 0 0.05'/>
            <geometry>
                <box size='0.2 0.2 0.1'/>
            </geometry>
            <material name="black"/>
        </visual>

        <collision>
            <origin xyz='0.1 0 0.05'/>
            <geometry>
                <box size='0.2 0.2 0.1'/>
            </geometry>
        </collision>
        <xacro:inertial_box mass='0.5' x='0.2' y='0.2' z='0.1'>
            <origin xyz='0.1 0 0.05' rpy='0 0 0'/>
        </xacro:inertial_box>
    </link>
    
    <gazebo reference='body'>
        <material>Gazebo/Black</material>
    </gazebo>

    <!--LEFT WHEEL LINK-->

    <joint name='left_wheel_joint' type='continuous'>
        <parent link='base_link'/>
        <child link='left_wheel_link'/>
        <origin xyz='-0.035 0.125 0.05' rpy='-${pi/2} 0 0'/>
        <axis xyz='0 0 1'/>
    </joint>

    <link name='left_wheel_link'>
        <visual>
            <geometry>
                <cylinder radius='0.06' length='0.05'/>
            </geometry>
            <material name='blue'/>
        </visual>

        <collision>
            <geometry>
                <cylinder radius='0.06' length='0.05'/>
            </geometry>
        </collision>
        <xacro:inertial_cylinder mass='0.1' length='0.05' radius='0.06'>
            <origin xyz='0 0 0' rpy='0 0 0'/>
        </xacro:inertial_cylinder>
    </link>

    <gazebo reference='left_wheel_link'>
        <material>Gazebo/Blue</material>
    </gazebo>

    <!--RIGHT WHEEL LINK-->

    <joint name='right_wheel_joint' type='continuous'>
        <parent link='base_link'/>
        <child link='right_wheel_link'/>
        <origin xyz='-0.035 -0.125 0.05' rpy='${pi/2} 0 0'/>
        <axis xyz='0 0 -1'/>
    </joint>

    <link name='right_wheel_link'>
        <visual>
            <geometry>
                <cylinder radius='0.06' length='0.05'/>
            </geometry>
            <material name='blue'/>
        </visual>

        <collision>
            <geometry>
                <cylinder radius='0.06' length='0.05'/>
            </geometry>
            
        </collision>
        <xacro:inertial_cylinder mass='0.1' length='0.05' radius='0.06'>
            <origin xyz='0 0 0' rpy='0 0 0'/>
        </xacro:inertial_cylinder>
    </link>

    <gazebo reference='right_wheel_link'>
        <material>Gazebo/Blue</material>
    </gazebo>

    <!--CASTER WHEEL-->

    <joint name='caster_wheel_joint' type='fixed'>
        <parent link='body'/>
        <child link='castor_wheel_link'/>
        <origin xyz='0.161 0 0'/>
    </joint>

    <link name='castor_wheel_link'>
        <visual>
            <geometry>
                <sphere radius='0.021'/>
            </geometry>
            <material name='white'/>
        </visual>

        <collision>
            <geometry>
                <sphere radius='0.021'/>
            </geometry>
        </collision>
        <xacro:inertial_sphere mass='0.1' radius='0.021'>
            <origin xyz='0 0 0' rpy='0 0 0'/>
        </xacro:inertial_sphere>
    </link>

    <gazebo reference='castor_wheel_link'>
        <material>Gazebo/White</material>
        <mu1 value='0.001'/>
        <mu2 value='0.001'/>
    </gazebo>

</robot>

